package ExceptionExamples;

public class FinallyBlock {
	public static void main(String args[]) {
		try {
			int data = 25 / 0;
			System.out.println(data);
		} catch (ArithmeticException e) {
			System.out.println("Arithmatic exception");
		} catch (NullPointerException e) {
			System.out.println(e);
		} finally {
			System.out.println("finally block is always executed");
		}
		System.out.println("came out of try catch finally block");
	}
}
